<?xml version="1.0" encoding="UTF-8"?>

<robot xmlns:xacro="http://www.ros.org/wiki/xacro" name="block-robotics">
	<link name="world" />

	<link name="base_link">
		<visual>
			<origin rpy="${pi/2} 0 0" xyz="0 0 0"/>
			<geometry>
				<mesh filename="package://robotic_arm_model/mesh/base_link.stl" scale="0.01 0.01 0.01"/>
			</geometry>
		</visual>
	</link>

	<joint name="virtual_joint" type="fixed">
		<parent link="world" />
		<child link="base_link" />
		<origin rpy="0 0 0" xyz="0 0 0" />
	</joint>

	<link name="link_1">
		<visual>
			<origin rpy="${pi/2} 0 0" xyz="0 0 0.5"/>
			<geometry>
				<mesh filename="package://robotic_arm_model/mesh/link_1.stl" scale="0.01 0.01 0.01"/>
			</geometry>
		</visual>
	</link>

	<joint name="joint_1" type="revolute">
		<parent link="base_link" />
		<child link="link_1" />
		<origin rpy="0 0 0" xyz="0 0 0" />
		<axis xyz="0 0 1"/>
		<limit lower="-${pi/2}" upper="${pi/2}" effort="30" velocity="10" />
	</joint>

	<link name="link_2">
		<visual>
			<origin rpy="${pi/2} 0 0" xyz="0 -0.21078 -0.28624"/>
			<geometry>
				<mesh filename="package://robotic_arm_model/mesh/link_2.stl" scale="0.01 0.01 0.01"/>
			</geometry>
		</visual>
	</link>

	<joint name="joint_2" type="revolute">
		<parent link="link_1" />
		<child link="link_2" />
		<origin rpy="0 0 0" xyz="0 0 0.95" />
		<axis xyz="1 0 0"/>
		<limit lower="-${pi/2}" upper="${pi/2}" effort="30" velocity="10" />
	</joint>

	<link name="link_3">
		<visual>
			<origin rpy="${pi/2} 0 0" xyz="0.03556 0 0"/>
			<geometry>
				<mesh filename="package://robotic_arm_model/mesh/link_3.stl" scale="0.01 0.01 0.01"/>
			</geometry>
		</visual>
	</link>

	<joint name="joint_3" type="revolute">
		<parent link="link_2" />
		<child link="link_3" />
		<origin rpy="0 0 0" xyz="0 0 1" />
		<axis xyz="1 0 0"/>
		<limit lower="-${pi/5}" upper="${4*pi/5}" effort="30" velocity="10" />
	</joint>

	<link name="link_4">
		<visual>
			<origin rpy="0 0 0" xyz="-0.2225 -0.35266 0.057835"/>
			<geometry>
				<mesh filename="package://robotic_arm_model/mesh/link_4.stl" scale="0.01 0.01 0.01"/>
			</geometry>
		</visual>
	</link>

	<joint name="joint_4" type="revolute">
		<parent link="link_3" />
		<child link="link_4" />
		<origin rpy="0 0 0" xyz="0 1.33701 0.057835" />
		<axis xyz="0 1 0"/>
		<limit lower="-${pi/2}" upper="${pi/2}" effort="30" velocity="10" />
	</joint>
	
	<link name="link_5">
		<visual>
			<origin rpy="0 ${pi} 0" xyz="0.0885 -0.32762 -0.5529"/>
			<geometry>
				<mesh filename="package://robotic_arm_model/mesh/link_5.stl" scale="0.01 0.01 0.01"/>
			</geometry>
		</visual>
	</link>

	<joint name="joint_5" type="revolute">
		<parent link="link_4" />
		<child link="link_5" />
		<origin rpy="0 0 0" xyz="0 0.4 0" />
		<axis xyz="1 0 0"/>
		<limit lower="0" upper="${pi}" effort="30" velocity="10" />
	</joint>

	<link name="end_effector_flange">
		<visual>
			<origin rpy="${pi/2} 0 0" xyz="0 0 -0.1644"/>
			<geometry>
				<mesh filename="package://robotic_arm_model/mesh/link_6.stl" scale="0.01 0.01 0.01"/>
			</geometry>
		</visual>
	</link>

	<joint name="joint_6" type="revolute">
		<parent link="link_5" />
		<child link="end_effector_flange" />
		<!-- 89475 -->
		<origin rpy="0 0 0" xyz="0 0 -0.73035" />
		<axis xyz="0 0 1"/>
		<limit lower="-${pi/2}" upper="${pi/2}" effort="30" velocity="10" />
	</joint>

</robot>
